[2024-05-15T20:54:50.298+0000] {local_task_job_runner.py:120} INFO - ::group::Pre task execution logs
[2024-05-15T20:54:50.352+0000] {taskinstance.py:2073} INFO - Dependencies all met for dep_context=non-requeueable deps ti=<TaskInstance: upload_csv_to_gcs_bucket.upload_task_0 manual__2024-05-15T14:39:24.008013+00:00 [queued]>
[2024-05-15T20:54:50.372+0000] {taskinstance.py:2073} INFO - Dependencies all met for dep_context=requeueable deps ti=<TaskInstance: upload_csv_to_gcs_bucket.upload_task_0 manual__2024-05-15T14:39:24.008013+00:00 [queued]>
[2024-05-15T20:54:50.376+0000] {taskinstance.py:2303} INFO - Starting attempt 5 of 6
[2024-05-15T20:54:50.413+0000] {taskinstance.py:2327} INFO - Executing <Task(LocalFilesystemToGCSOperator): upload_task_0> on 2024-05-15 14:39:24.008013+00:00
[2024-05-15T20:54:50.429+0000] {warnings.py:110} WARNING - /home/***/.local/lib/python3.12/site-packages/***/task/task_runner/standard_task_runner.py:61: DeprecationWarning: This process (pid=304) is multi-threaded, use of fork() may lead to deadlocks in the child.
  pid = os.fork()

[2024-05-15T20:54:50.436+0000] {standard_task_runner.py:63} INFO - Started process 317 to run task
[2024-05-15T20:54:50.430+0000] {standard_task_runner.py:90} INFO - Running: ['***', 'tasks', 'run', 'upload_csv_to_gcs_bucket', 'upload_task_0', 'manual__2024-05-15T14:39:24.008013+00:00', '--job-id', '948', '--raw', '--subdir', 'DAGS_FOLDER/gcp_csv_upload.py', '--cfg-path', '/tmp/tmpwwzj38o0']
[2024-05-15T20:54:50.440+0000] {standard_task_runner.py:91} INFO - Job 948: Subtask upload_task_0
[2024-05-15T20:54:50.475+0000] {warnings.py:110} WARNING - /home/***/.local/lib/python3.12/site-packages/***/settings.py:195: DeprecationWarning: The sql_alchemy_conn option in [core] has been moved to the sql_alchemy_conn option in [database] - the old setting has been used, but please update your config.
  SQL_ALCHEMY_CONN = conf.get("database", "SQL_ALCHEMY_CONN")

[2024-05-15T20:54:50.572+0000] {task_command.py:426} INFO - Running <TaskInstance: upload_csv_to_gcs_bucket.upload_task_0 manual__2024-05-15T14:39:24.008013+00:00 [running]> on host e9b4a57d7285
[2024-05-15T20:54:50.794+0000] {taskinstance.py:2644} INFO - Exporting env vars: AIRFLOW_CTX_DAG_OWNER='***' AIRFLOW_CTX_DAG_ID='upload_csv_to_gcs_bucket' AIRFLOW_CTX_TASK_ID='upload_task_0' AIRFLOW_CTX_EXECUTION_DATE='2024-05-15T14:39:24.008013+00:00' AIRFLOW_CTX_TRY_NUMBER='5' AIRFLOW_CTX_DAG_RUN_ID='manual__2024-05-15T14:39:24.008013+00:00'
[2024-05-15T20:54:50.798+0000] {taskinstance.py:430} INFO - ::endgroup::
[2024-05-15T20:54:50.844+0000] {connection.py:274} WARNING - Connection schemes (type: google_cloud_platform) shall not contain '_' according to RFC3986.
[2024-05-15T20:54:50.855+0000] {base.py:84} INFO - Using connection ID 'google_cloud_default' for task execution.
[2024-05-15T20:54:50.857+0000] {taskinstance.py:441} INFO - ::group::Post task execution logs
[2024-05-15T20:54:50.860+0000] {taskinstance.py:2890} ERROR - Task failed with exception
Traceback (most recent call last):
  File "/home/airflow/.local/lib/python3.12/site-packages/airflow/models/taskinstance.py", line 465, in _execute_task
    result = _execute_callable(context=context, **execute_callable_kwargs)
             ^^^^^^^^^^^^^^^^^^^^^^^^^^^^^^^^^^^^^^^^^^^^^^^^^^^^^^^^^^^^^
  File "/home/airflow/.local/lib/python3.12/site-packages/airflow/models/taskinstance.py", line 432, in _execute_callable
    return execute_callable(context=context, **execute_callable_kwargs)
           ^^^^^^^^^^^^^^^^^^^^^^^^^^^^^^^^^^^^^^^^^^^^^^^^^^^^^^^^^^^^
  File "/home/airflow/.local/lib/python3.12/site-packages/airflow/models/baseoperator.py", line 400, in wrapper
    return func(self, *args, **kwargs)
           ^^^^^^^^^^^^^^^^^^^^^^^^^^^
  File "/home/airflow/.local/lib/python3.12/site-packages/airflow/providers/google/cloud/transfers/local_to_gcs.py", line 97, in execute
    raise FileNotFoundError(self.src)
FileNotFoundError: /data/sales_2024-05-15.csv
[2024-05-15T20:54:50.881+0000] {taskinstance.py:1205} INFO - Marking task as UP_FOR_RETRY. dag_id=upload_csv_to_gcs_bucket, task_id=upload_task_0, execution_date=20240515T143924, start_date=20240515T205450, end_date=20240515T205450
[2024-05-15T20:54:50.903+0000] {standard_task_runner.py:110} ERROR - Failed to execute job 948 for task upload_task_0 (/data/sales_2024-05-15.csv; 317)
[2024-05-15T20:54:50.942+0000] {local_task_job_runner.py:240} INFO - Task exited with return code 1
[2024-05-15T20:54:50.985+0000] {taskinstance.py:3482} INFO - 0 downstream tasks scheduled from follow-on schedule check
[2024-05-15T20:54:50.991+0000] {local_task_job_runner.py:222} INFO - ::endgroup::
