[2024-05-13T20:05:53.333+0000] {local_task_job_runner.py:120} INFO - ::group::Pre task execution logs
[2024-05-13T20:05:53.349+0000] {taskinstance.py:2073} INFO - Dependencies all met for dep_context=non-requeueable deps ti=<TaskInstance: gcs_upload_example.upload_file_to_gcs manual__2024-05-13T20:00:49.143534+00:00 [queued]>
[2024-05-13T20:05:53.357+0000] {taskinstance.py:2073} INFO - Dependencies all met for dep_context=requeueable deps ti=<TaskInstance: gcs_upload_example.upload_file_to_gcs manual__2024-05-13T20:00:49.143534+00:00 [queued]>
[2024-05-13T20:05:53.357+0000] {taskinstance.py:2303} INFO - Starting attempt 2 of 2
[2024-05-13T20:05:53.371+0000] {taskinstance.py:2327} INFO - Executing <Task(LocalFilesystemToGCSOperator): upload_file_to_gcs> on 2024-05-13 20:00:49.143534+00:00
[2024-05-13T20:05:53.379+0000] {warnings.py:110} WARNING - /home/***/.local/lib/python3.12/site-packages/***/task/task_runner/standard_task_runner.py:61: DeprecationWarning: This process (pid=87) is multi-threaded, use of fork() may lead to deadlocks in the child.
  pid = os.fork()

[2024-05-13T20:05:53.380+0000] {standard_task_runner.py:63} INFO - Started process 88 to run task
[2024-05-13T20:05:53.380+0000] {standard_task_runner.py:90} INFO - Running: ['***', 'tasks', 'run', 'gcs_upload_example', 'upload_file_to_gcs', 'manual__2024-05-13T20:00:49.143534+00:00', '--job-id', '16', '--raw', '--subdir', 'DAGS_FOLDER/gcp_example.py', '--cfg-path', '/tmp/tmplxx9xhpf']
[2024-05-13T20:05:53.381+0000] {standard_task_runner.py:91} INFO - Job 16: Subtask upload_file_to_gcs
[2024-05-13T20:05:53.396+0000] {warnings.py:110} WARNING - /home/***/.local/lib/python3.12/site-packages/***/settings.py:195: DeprecationWarning: The sql_alchemy_conn option in [core] has been moved to the sql_alchemy_conn option in [database] - the old setting has been used, but please update your config.
  SQL_ALCHEMY_CONN = conf.get("database", "SQL_ALCHEMY_CONN")

[2024-05-13T20:05:53.434+0000] {task_command.py:426} INFO - Running <TaskInstance: gcs_upload_example.upload_file_to_gcs manual__2024-05-13T20:00:49.143534+00:00 [running]> on host 81927d469f95
[2024-05-13T20:05:53.519+0000] {taskinstance.py:2644} INFO - Exporting env vars: AIRFLOW_CTX_DAG_EMAIL='your-email@example.com' AIRFLOW_CTX_DAG_OWNER='***' AIRFLOW_CTX_DAG_ID='gcs_upload_example' AIRFLOW_CTX_TASK_ID='upload_file_to_gcs' AIRFLOW_CTX_EXECUTION_DATE='2024-05-13T20:00:49.143534+00:00' AIRFLOW_CTX_TRY_NUMBER='2' AIRFLOW_CTX_DAG_RUN_ID='manual__2024-05-13T20:00:49.143534+00:00'
[2024-05-13T20:05:53.520+0000] {taskinstance.py:430} INFO - ::endgroup::
[2024-05-13T20:05:53.540+0000] {connection.py:274} WARNING - Connection schemes (type: google_cloud_platform) shall not contain '_' according to RFC3986.
[2024-05-13T20:05:53.543+0000] {base.py:84} INFO - Using connection ID 'google_cloud_default' for task execution.
[2024-05-13T20:05:53.545+0000] {taskinstance.py:441} INFO - ::group::Post task execution logs
[2024-05-13T20:05:53.555+0000] {taskinstance.py:2890} ERROR - Task failed with exception
Traceback (most recent call last):
  File "/home/airflow/.local/lib/python3.12/site-packages/airflow/providers/google/common/hooks/base_google.py", line 268, in get_credentials_and_project_id
    keyfile_dict_json = json.loads(keyfile_dict)
                        ^^^^^^^^^^^^^^^^^^^^^^^^
  File "/usr/local/lib/python3.12/json/__init__.py", line 346, in loads
    return _default_decoder.decode(s)
           ^^^^^^^^^^^^^^^^^^^^^^^^^^
  File "/usr/local/lib/python3.12/json/decoder.py", line 337, in decode
    obj, end = self.raw_decode(s, idx=_w(s, 0).end())
               ^^^^^^^^^^^^^^^^^^^^^^^^^^^^^^^^^^^^^^
  File "/usr/local/lib/python3.12/json/decoder.py", line 355, in raw_decode
    raise JSONDecodeError("Expecting value", s, err.value) from None
json.decoder.JSONDecodeError: Expecting value: line 1 column 1 (char 0)

During handling of the above exception, another exception occurred:

Traceback (most recent call last):
  File "/home/airflow/.local/lib/python3.12/site-packages/airflow/models/taskinstance.py", line 465, in _execute_task
    result = _execute_callable(context=context, **execute_callable_kwargs)
             ^^^^^^^^^^^^^^^^^^^^^^^^^^^^^^^^^^^^^^^^^^^^^^^^^^^^^^^^^^^^^
  File "/home/airflow/.local/lib/python3.12/site-packages/airflow/models/taskinstance.py", line 432, in _execute_callable
    return execute_callable(context=context, **execute_callable_kwargs)
           ^^^^^^^^^^^^^^^^^^^^^^^^^^^^^^^^^^^^^^^^^^^^^^^^^^^^^^^^^^^^
  File "/home/airflow/.local/lib/python3.12/site-packages/airflow/models/baseoperator.py", line 400, in wrapper
    return func(self, *args, **kwargs)
           ^^^^^^^^^^^^^^^^^^^^^^^^^^^
  File "/home/airflow/.local/lib/python3.12/site-packages/airflow/providers/google/cloud/transfers/local_to_gcs.py", line 110, in execute
    hook.upload(
  File "/home/airflow/.local/lib/python3.12/site-packages/airflow/providers/google/cloud/hooks/gcs.py", line 525, in upload
    client = self.get_conn()
             ^^^^^^^^^^^^^^^
  File "/home/airflow/.local/lib/python3.12/site-packages/airflow/providers/google/cloud/hooks/gcs.py", line 168, in get_conn
    credentials=self.get_credentials(), client_info=CLIENT_INFO, project=self.project_id
                ^^^^^^^^^^^^^^^^^^^^^^
  File "/home/airflow/.local/lib/python3.12/site-packages/airflow/providers/google/common/hooks/base_google.py", line 307, in get_credentials
    credentials, _ = self.get_credentials_and_project_id()
                     ^^^^^^^^^^^^^^^^^^^^^^^^^^^^^^^^^^^^^
  File "/home/airflow/.local/lib/python3.12/site-packages/airflow/providers/google/common/hooks/base_google.py", line 270, in get_credentials_and_project_id
    raise AirflowException("Invalid key JSON.")
airflow.exceptions.AirflowException: Invalid key JSON.
[2024-05-13T20:05:53.560+0000] {taskinstance.py:1205} INFO - Marking task as FAILED. dag_id=gcs_upload_example, task_id=upload_file_to_gcs, execution_date=20240513T200049, start_date=20240513T200553, end_date=20240513T200553
[2024-05-13T20:05:53.578+0000] {standard_task_runner.py:110} ERROR - Failed to execute job 16 for task upload_file_to_gcs (Invalid key JSON.; 88)
[2024-05-13T20:05:53.594+0000] {local_task_job_runner.py:240} INFO - Task exited with return code 1
[2024-05-13T20:05:53.611+0000] {taskinstance.py:3482} INFO - 0 downstream tasks scheduled from follow-on schedule check
[2024-05-13T20:05:53.615+0000] {local_task_job_runner.py:222} INFO - ::endgroup::
