[2024-05-13T20:45:25.287+0000] {local_task_job_runner.py:120} INFO - ::group::Pre task execution logs
[2024-05-13T20:45:25.317+0000] {taskinstance.py:2073} INFO - Dependencies all met for dep_context=non-requeueable deps ti=<TaskInstance: gcs_upload_example.upload_file_to_gcs manual__2024-05-13T20:24:37.408335+00:00 [queued]>
[2024-05-13T20:45:25.330+0000] {taskinstance.py:2073} INFO - Dependencies all met for dep_context=requeueable deps ti=<TaskInstance: gcs_upload_example.upload_file_to_gcs manual__2024-05-13T20:24:37.408335+00:00 [queued]>
[2024-05-13T20:45:25.334+0000] {taskinstance.py:2303} INFO - Starting attempt 4 of 5
[2024-05-13T20:45:25.432+0000] {taskinstance.py:2327} INFO - Executing <Task(LocalFilesystemToGCSOperator): upload_file_to_gcs> on 2024-05-13 20:24:37.408335+00:00
[2024-05-13T20:45:25.441+0000] {warnings.py:110} WARNING - /home/***/.local/lib/python3.12/site-packages/***/task/task_runner/standard_task_runner.py:61: DeprecationWarning: This process (pid=64) is multi-threaded, use of fork() may lead to deadlocks in the child.
  pid = os.fork()

[2024-05-13T20:45:25.443+0000] {standard_task_runner.py:63} INFO - Started process 71 to run task
[2024-05-13T20:45:25.445+0000] {standard_task_runner.py:90} INFO - Running: ['***', 'tasks', 'run', 'gcs_upload_example', 'upload_file_to_gcs', 'manual__2024-05-13T20:24:37.408335+00:00', '--job-id', '51', '--raw', '--subdir', 'DAGS_FOLDER/gcp_example.py', '--cfg-path', '/tmp/tmp8ltcqqd9']
[2024-05-13T20:45:25.448+0000] {standard_task_runner.py:91} INFO - Job 51: Subtask upload_file_to_gcs
[2024-05-13T20:45:25.483+0000] {warnings.py:110} WARNING - /home/***/.local/lib/python3.12/site-packages/***/settings.py:195: DeprecationWarning: The sql_alchemy_conn option in [core] has been moved to the sql_alchemy_conn option in [database] - the old setting has been used, but please update your config.
  SQL_ALCHEMY_CONN = conf.get("database", "SQL_ALCHEMY_CONN")

[2024-05-13T20:45:25.526+0000] {task_command.py:426} INFO - Running <TaskInstance: gcs_upload_example.upload_file_to_gcs manual__2024-05-13T20:24:37.408335+00:00 [running]> on host 9df925c47a8b
[2024-05-13T20:45:25.694+0000] {taskinstance.py:2644} INFO - Exporting env vars: AIRFLOW_CTX_DAG_EMAIL='your-email@example.com' AIRFLOW_CTX_DAG_OWNER='***' AIRFLOW_CTX_DAG_ID='gcs_upload_example' AIRFLOW_CTX_TASK_ID='upload_file_to_gcs' AIRFLOW_CTX_EXECUTION_DATE='2024-05-13T20:24:37.408335+00:00' AIRFLOW_CTX_TRY_NUMBER='4' AIRFLOW_CTX_DAG_RUN_ID='manual__2024-05-13T20:24:37.408335+00:00'
[2024-05-13T20:45:25.696+0000] {taskinstance.py:430} INFO - ::endgroup::
[2024-05-13T20:45:25.730+0000] {connection.py:274} WARNING - Connection schemes (type: google_cloud_platform) shall not contain '_' according to RFC3986.
[2024-05-13T20:45:25.736+0000] {base.py:84} INFO - Using connection ID 'google_cloud_default' for task execution.
[2024-05-13T20:45:25.738+0000] {taskinstance.py:441} INFO - ::group::Post task execution logs
[2024-05-13T20:45:25.753+0000] {taskinstance.py:2890} ERROR - Task failed with exception
Traceback (most recent call last):
  File "/home/airflow/.local/lib/python3.12/site-packages/airflow/providers/google/common/hooks/base_google.py", line 268, in get_credentials_and_project_id
    keyfile_dict_json = json.loads(keyfile_dict)
                        ^^^^^^^^^^^^^^^^^^^^^^^^
  File "/usr/local/lib/python3.12/json/__init__.py", line 346, in loads
    return _default_decoder.decode(s)
           ^^^^^^^^^^^^^^^^^^^^^^^^^^
  File "/usr/local/lib/python3.12/json/decoder.py", line 337, in decode
    obj, end = self.raw_decode(s, idx=_w(s, 0).end())
               ^^^^^^^^^^^^^^^^^^^^^^^^^^^^^^^^^^^^^^
  File "/usr/local/lib/python3.12/json/decoder.py", line 355, in raw_decode
    raise JSONDecodeError("Expecting value", s, err.value) from None
json.decoder.JSONDecodeError: Expecting value: line 1 column 1 (char 0)

During handling of the above exception, another exception occurred:

Traceback (most recent call last):
  File "/home/airflow/.local/lib/python3.12/site-packages/airflow/models/taskinstance.py", line 465, in _execute_task
    result = _execute_callable(context=context, **execute_callable_kwargs)
             ^^^^^^^^^^^^^^^^^^^^^^^^^^^^^^^^^^^^^^^^^^^^^^^^^^^^^^^^^^^^^
  File "/home/airflow/.local/lib/python3.12/site-packages/airflow/models/taskinstance.py", line 432, in _execute_callable
    return execute_callable(context=context, **execute_callable_kwargs)
           ^^^^^^^^^^^^^^^^^^^^^^^^^^^^^^^^^^^^^^^^^^^^^^^^^^^^^^^^^^^^
  File "/home/airflow/.local/lib/python3.12/site-packages/airflow/models/baseoperator.py", line 400, in wrapper
    return func(self, *args, **kwargs)
           ^^^^^^^^^^^^^^^^^^^^^^^^^^^
  File "/home/airflow/.local/lib/python3.12/site-packages/airflow/providers/google/cloud/transfers/local_to_gcs.py", line 110, in execute
    hook.upload(
  File "/home/airflow/.local/lib/python3.12/site-packages/airflow/providers/google/cloud/hooks/gcs.py", line 525, in upload
    client = self.get_conn()
             ^^^^^^^^^^^^^^^
  File "/home/airflow/.local/lib/python3.12/site-packages/airflow/providers/google/cloud/hooks/gcs.py", line 168, in get_conn
    credentials=self.get_credentials(), client_info=CLIENT_INFO, project=self.project_id
                ^^^^^^^^^^^^^^^^^^^^^^
  File "/home/airflow/.local/lib/python3.12/site-packages/airflow/providers/google/common/hooks/base_google.py", line 307, in get_credentials
    credentials, _ = self.get_credentials_and_project_id()
                     ^^^^^^^^^^^^^^^^^^^^^^^^^^^^^^^^^^^^^
  File "/home/airflow/.local/lib/python3.12/site-packages/airflow/providers/google/common/hooks/base_google.py", line 270, in get_credentials_and_project_id
    raise AirflowException("Invalid key JSON.")
airflow.exceptions.AirflowException: Invalid key JSON.
[2024-05-13T20:45:25.761+0000] {taskinstance.py:1205} INFO - Marking task as UP_FOR_RETRY. dag_id=gcs_upload_example, task_id=upload_file_to_gcs, execution_date=20240513T202437, start_date=20240513T204525, end_date=20240513T204525
[2024-05-13T20:45:25.850+0000] {standard_task_runner.py:110} ERROR - Failed to execute job 51 for task upload_file_to_gcs (Invalid key JSON.; 71)
[2024-05-13T20:45:25.898+0000] {local_task_job_runner.py:240} INFO - Task exited with return code 1
[2024-05-13T20:45:25.924+0000] {taskinstance.py:3482} INFO - 0 downstream tasks scheduled from follow-on schedule check
[2024-05-13T20:45:25.969+0000] {local_task_job_runner.py:222} INFO - ::endgroup::
