[2024-05-15T14:40:23.238+0000] {local_task_job_runner.py:120} INFO - ::group::Pre task execution logs
[2024-05-15T14:40:23.298+0000] {taskinstance.py:2073} INFO - Dependencies all met for dep_context=non-requeueable deps ti=<TaskInstance: upload_csv_to_gcs_bucket.upload_task_1 scheduled__2022-08-19T00:00:00+00:00 [queued]>
[2024-05-15T14:40:23.319+0000] {taskinstance.py:2073} INFO - Dependencies all met for dep_context=requeueable deps ti=<TaskInstance: upload_csv_to_gcs_bucket.upload_task_1 scheduled__2022-08-19T00:00:00+00:00 [queued]>
[2024-05-15T14:40:23.321+0000] {taskinstance.py:2303} INFO - Starting attempt 11 of 12
[2024-05-15T14:40:23.380+0000] {taskinstance.py:2327} INFO - Executing <Task(LocalFilesystemToGCSOperator): upload_task_1> on 2022-08-19 00:00:00+00:00
[2024-05-15T14:40:23.421+0000] {warnings.py:110} WARNING - /home/***/.local/lib/python3.12/site-packages/***/task/task_runner/standard_task_runner.py:61: DeprecationWarning: This process (pid=862) is multi-threaded, use of fork() may lead to deadlocks in the child.
  pid = os.fork()

[2024-05-15T14:40:23.417+0000] {standard_task_runner.py:90} INFO - Running: ['***', 'tasks', 'run', 'upload_csv_to_gcs_bucket', 'upload_task_1', 'scheduled__2022-08-19T00:00:00+00:00', '--job-id', '731', '--raw', '--subdir', 'DAGS_FOLDER/gcp_csv_upload.py', '--cfg-path', '/tmp/tmp_i7x9p6_']
[2024-05-15T14:40:23.439+0000] {standard_task_runner.py:63} INFO - Started process 878 to run task
[2024-05-15T14:40:23.440+0000] {standard_task_runner.py:91} INFO - Job 731: Subtask upload_task_1
[2024-05-15T14:40:23.511+0000] {warnings.py:110} WARNING - /home/***/.local/lib/python3.12/site-packages/***/settings.py:195: DeprecationWarning: The sql_alchemy_conn option in [core] has been moved to the sql_alchemy_conn option in [database] - the old setting has been used, but please update your config.
  SQL_ALCHEMY_CONN = conf.get("database", "SQL_ALCHEMY_CONN")

[2024-05-15T14:40:23.648+0000] {task_command.py:426} INFO - Running <TaskInstance: upload_csv_to_gcs_bucket.upload_task_1 scheduled__2022-08-19T00:00:00+00:00 [running]> on host e9b4a57d7285
[2024-05-15T14:40:23.904+0000] {taskinstance.py:2644} INFO - Exporting env vars: AIRFLOW_CTX_DAG_EMAIL='your@email.com' AIRFLOW_CTX_DAG_OWNER='***' AIRFLOW_CTX_DAG_ID='upload_csv_to_gcs_bucket' AIRFLOW_CTX_TASK_ID='upload_task_1' AIRFLOW_CTX_EXECUTION_DATE='2022-08-19T00:00:00+00:00' AIRFLOW_CTX_TRY_NUMBER='11' AIRFLOW_CTX_DAG_RUN_ID='scheduled__2022-08-19T00:00:00+00:00'
[2024-05-15T14:40:23.912+0000] {taskinstance.py:430} INFO - ::endgroup::
[2024-05-15T14:40:23.969+0000] {connection.py:274} WARNING - Connection schemes (type: google_cloud_platform) shall not contain '_' according to RFC3986.
[2024-05-15T14:40:23.975+0000] {base.py:84} INFO - Using connection ID 'google_cloud_default' for task execution.
[2024-05-15T14:40:23.977+0000] {taskinstance.py:441} INFO - ::group::Post task execution logs
[2024-05-15T14:40:23.981+0000] {taskinstance.py:2890} ERROR - Task failed with exception
Traceback (most recent call last):
  File "/home/airflow/.local/lib/python3.12/site-packages/airflow/models/taskinstance.py", line 465, in _execute_task
    result = _execute_callable(context=context, **execute_callable_kwargs)
             ^^^^^^^^^^^^^^^^^^^^^^^^^^^^^^^^^^^^^^^^^^^^^^^^^^^^^^^^^^^^^
  File "/home/airflow/.local/lib/python3.12/site-packages/airflow/models/taskinstance.py", line 432, in _execute_callable
    return execute_callable(context=context, **execute_callable_kwargs)
           ^^^^^^^^^^^^^^^^^^^^^^^^^^^^^^^^^^^^^^^^^^^^^^^^^^^^^^^^^^^^
  File "/home/airflow/.local/lib/python3.12/site-packages/airflow/models/baseoperator.py", line 400, in wrapper
    return func(self, *args, **kwargs)
           ^^^^^^^^^^^^^^^^^^^^^^^^^^^
  File "/home/airflow/.local/lib/python3.12/site-packages/airflow/providers/google/cloud/transfers/local_to_gcs.py", line 97, in execute
    raise FileNotFoundError(self.src)
FileNotFoundError: /data/sales_2022-08-19.csv
[2024-05-15T14:40:24.002+0000] {taskinstance.py:1205} INFO - Marking task as UP_FOR_RETRY. dag_id=upload_csv_to_gcs_bucket, task_id=upload_task_1, execution_date=20220819T000000, start_date=20240515T144023, end_date=20240515T144024
[2024-05-15T14:40:24.035+0000] {standard_task_runner.py:110} ERROR - Failed to execute job 731 for task upload_task_1 (/data/sales_2022-08-19.csv; 878)
[2024-05-15T14:40:24.065+0000] {local_task_job_runner.py:240} INFO - Task exited with return code 1
[2024-05-15T14:40:24.108+0000] {taskinstance.py:3482} INFO - 0 downstream tasks scheduled from follow-on schedule check
[2024-05-15T14:40:24.115+0000] {local_task_job_runner.py:222} INFO - ::endgroup::
