[2024-05-15T13:40:46.209+0000] {local_task_job_runner.py:120} INFO - ::group::Pre task execution logs
[2024-05-15T13:40:46.244+0000] {taskinstance.py:2073} INFO - Dependencies all met for dep_context=non-requeueable deps ti=<TaskInstance: gcs_upload_example.upload_file_to_gcs manual__2024-05-13T21:22:15.823713+00:00 [queued]>
[2024-05-15T13:40:46.263+0000] {taskinstance.py:2073} INFO - Dependencies all met for dep_context=requeueable deps ti=<TaskInstance: gcs_upload_example.upload_file_to_gcs manual__2024-05-13T21:22:15.823713+00:00 [queued]>
[2024-05-15T13:40:46.266+0000] {taskinstance.py:2303} INFO - Starting attempt 18 of 19
[2024-05-15T13:40:46.293+0000] {taskinstance.py:2327} INFO - Executing <Task(LocalFilesystemToGCSOperator): upload_file_to_gcs> on 2024-05-13 21:22:15.823713+00:00
[2024-05-15T13:40:46.304+0000] {warnings.py:110} WARNING - /home/***/.local/lib/python3.12/site-packages/***/task/task_runner/standard_task_runner.py:61: DeprecationWarning: This process (pid=133) is multi-threaded, use of fork() may lead to deadlocks in the child.
  pid = os.fork()

[2024-05-15T13:40:46.307+0000] {standard_task_runner.py:63} INFO - Started process 158 to run task
[2024-05-15T13:40:46.312+0000] {standard_task_runner.py:90} INFO - Running: ['***', 'tasks', 'run', 'gcs_upload_example', 'upload_file_to_gcs', 'manual__2024-05-13T21:22:15.823713+00:00', '--job-id', '376', '--raw', '--subdir', 'DAGS_FOLDER/gcp_example.py', '--cfg-path', '/tmp/tmp8howdjvg']
[2024-05-15T13:40:46.316+0000] {standard_task_runner.py:91} INFO - Job 376: Subtask upload_file_to_gcs
[2024-05-15T13:40:46.347+0000] {warnings.py:110} WARNING - /home/***/.local/lib/python3.12/site-packages/***/settings.py:195: DeprecationWarning: The sql_alchemy_conn option in [core] has been moved to the sql_alchemy_conn option in [database] - the old setting has been used, but please update your config.
  SQL_ALCHEMY_CONN = conf.get("database", "SQL_ALCHEMY_CONN")

[2024-05-15T13:40:46.420+0000] {task_command.py:426} INFO - Running <TaskInstance: gcs_upload_example.upload_file_to_gcs manual__2024-05-13T21:22:15.823713+00:00 [running]> on host e9b4a57d7285
[2024-05-15T13:40:46.594+0000] {taskinstance.py:2644} INFO - Exporting env vars: AIRFLOW_CTX_DAG_EMAIL='your-email@example.com' AIRFLOW_CTX_DAG_OWNER='***' AIRFLOW_CTX_DAG_ID='gcs_upload_example' AIRFLOW_CTX_TASK_ID='upload_file_to_gcs' AIRFLOW_CTX_EXECUTION_DATE='2024-05-13T21:22:15.823713+00:00' AIRFLOW_CTX_TRY_NUMBER='18' AIRFLOW_CTX_DAG_RUN_ID='manual__2024-05-13T21:22:15.823713+00:00'
[2024-05-15T13:40:46.599+0000] {taskinstance.py:430} INFO - ::endgroup::
[2024-05-15T13:40:46.650+0000] {connection.py:274} WARNING - Connection schemes (type: google_cloud_platform) shall not contain '_' according to RFC3986.
[2024-05-15T13:40:46.657+0000] {base.py:84} INFO - Using connection ID 'google_cloud_default' for task execution.
[2024-05-15T13:40:47.368+0000] {gcs.py:512} ERROR - Upload attempt of object: 2024-05-13/2024-05-13.csv from 2024-05-13/2024-05-13.csv has failed. Attempt: 1, max 1.
[2024-05-15T13:40:47.369+0000] {taskinstance.py:441} INFO - ::group::Post task execution logs
[2024-05-15T13:40:47.370+0000] {taskinstance.py:2890} ERROR - Task failed with exception
Traceback (most recent call last):
  File "/home/airflow/.local/lib/python3.12/site-packages/google/cloud/storage/blob.py", line 2637, in _prep_and_do_upload
    created_json = self._do_upload(
                   ^^^^^^^^^^^^^^^^
  File "/home/airflow/.local/lib/python3.12/site-packages/google/cloud/storage/blob.py", line 2443, in _do_upload
    response = self._do_multipart_upload(
               ^^^^^^^^^^^^^^^^^^^^^^^^^^
  File "/home/airflow/.local/lib/python3.12/site-packages/google/cloud/storage/blob.py", line 1956, in _do_multipart_upload
    response = upload.transmit(
               ^^^^^^^^^^^^^^^^
  File "/home/airflow/.local/lib/python3.12/site-packages/google/resumable_media/requests/upload.py", line 153, in transmit
    return _request_helpers.wait_and_retry(
           ^^^^^^^^^^^^^^^^^^^^^^^^^^^^^^^^
  File "/home/airflow/.local/lib/python3.12/site-packages/google/resumable_media/requests/_request_helpers.py", line 178, in wait_and_retry
    raise error
  File "/home/airflow/.local/lib/python3.12/site-packages/google/resumable_media/requests/_request_helpers.py", line 155, in wait_and_retry
    response = func()
               ^^^^^^
  File "/home/airflow/.local/lib/python3.12/site-packages/google/resumable_media/requests/upload.py", line 149, in retriable_request
    self._process_response(result)
  File "/home/airflow/.local/lib/python3.12/site-packages/google/resumable_media/_upload.py", line 125, in _process_response
    _helpers.require_status_code(response, (http.client.OK,), self._get_status_code)
  File "/home/airflow/.local/lib/python3.12/site-packages/google/resumable_media/_helpers.py", line 108, in require_status_code
    raise common.InvalidResponse(
google.resumable_media.common.InvalidResponse: ('Request failed with status code', 429, 'Expected one of', 200)

During handling of the above exception, another exception occurred:

Traceback (most recent call last):
  File "/home/airflow/.local/lib/python3.12/site-packages/airflow/models/taskinstance.py", line 465, in _execute_task
    result = _execute_callable(context=context, **execute_callable_kwargs)
             ^^^^^^^^^^^^^^^^^^^^^^^^^^^^^^^^^^^^^^^^^^^^^^^^^^^^^^^^^^^^^
  File "/home/airflow/.local/lib/python3.12/site-packages/airflow/models/taskinstance.py", line 432, in _execute_callable
    return execute_callable(context=context, **execute_callable_kwargs)
           ^^^^^^^^^^^^^^^^^^^^^^^^^^^^^^^^^^^^^^^^^^^^^^^^^^^^^^^^^^^^
  File "/home/airflow/.local/lib/python3.12/site-packages/airflow/models/baseoperator.py", line 400, in wrapper
    return func(self, *args, **kwargs)
           ^^^^^^^^^^^^^^^^^^^^^^^^^^^
  File "/home/airflow/.local/lib/python3.12/site-packages/airflow/providers/google/cloud/transfers/local_to_gcs.py", line 110, in execute
    hook.upload(
  File "/home/airflow/.local/lib/python3.12/site-packages/airflow/providers/google/cloud/hooks/gcs.py", line 551, in upload
    _call_with_retry(
  File "/home/airflow/.local/lib/python3.12/site-packages/airflow/providers/google/cloud/hooks/gcs.py", line 519, in _call_with_retry
    raise e
  File "/home/airflow/.local/lib/python3.12/site-packages/airflow/providers/google/cloud/hooks/gcs.py", line 509, in _call_with_retry
    f()
  File "/home/airflow/.local/lib/python3.12/site-packages/google/cloud/storage/blob.py", line 2959, in upload_from_filename
    self._handle_filename_and_upload(
  File "/home/airflow/.local/lib/python3.12/site-packages/google/cloud/storage/blob.py", line 2829, in _handle_filename_and_upload
    self._prep_and_do_upload(
  File "/home/airflow/.local/lib/python3.12/site-packages/google/cloud/storage/blob.py", line 2655, in _prep_and_do_upload
    _raise_from_invalid_response(exc)
  File "/home/airflow/.local/lib/python3.12/site-packages/google/cloud/storage/blob.py", line 4847, in _raise_from_invalid_response
    raise exceptions.from_http_status(response.status_code, message, response=response)
google.api_core.exceptions.TooManyRequests: 429 POST https://storage.googleapis.com/upload/storage/v1/b/de-07-data-bucket/o?uploadType=multipart: {
  "error": {
    "code": 429,
    "message": "The object de-07-data-bucket/2024-05-13/2024-05-13.csv exceeded the rate limit for object mutation operations (create, update, and delete). Please reduce your request rate. See https://cloud.google.com/storage/docs/gcs429.",
    "errors": [
      {
        "message": "The object de-07-data-bucket/2024-05-13/2024-05-13.csv exceeded the rate limit for object mutation operations (create, update, and delete). Please reduce your request rate. See https://cloud.google.com/storage/docs/gcs429.",
        "domain": "usageLimits",
        "reason": "rateLimitExceeded"
      }
    ]
  }
}
: ('Request failed with status code', 429, 'Expected one of', <HTTPStatus.OK: 200>)
[2024-05-15T13:40:47.389+0000] {taskinstance.py:1205} INFO - Marking task as UP_FOR_RETRY. dag_id=gcs_upload_example, task_id=upload_file_to_gcs, execution_date=20240513T212215, start_date=20240515T134046, end_date=20240515T134047
[2024-05-15T13:40:47.405+0000] {standard_task_runner.py:110} ERROR - Failed to execute job 376 for task upload_file_to_gcs (429 POST https://storage.googleapis.com/upload/storage/v1/b/de-07-data-bucket/o?uploadType=multipart: {
  "error": {
    "code": 429,
    "message": "The object de-07-data-bucket/2024-05-13/2024-05-13.csv exceeded the rate limit for object mutation operations (create, update, and delete). Please reduce your request rate. See https://cloud.google.com/storage/docs/gcs429.",
    "errors": [
      {
        "message": "The object de-07-data-bucket/2024-05-13/2024-05-13.csv exceeded the rate limit for object mutation operations (create, update, and delete). Please reduce your request rate. See https://cloud.google.com/storage/docs/gcs429.",
        "domain": "usageLimits",
        "reason": "rateLimitExceeded"
      }
    ]
  }
}
: ('Request failed with status code', 429, 'Expected one of', <HTTPStatus.OK: 200>); 158)
[2024-05-15T13:40:47.447+0000] {local_task_job_runner.py:240} INFO - Task exited with return code 1
[2024-05-15T13:40:47.470+0000] {taskinstance.py:3482} INFO - 0 downstream tasks scheduled from follow-on schedule check
[2024-05-15T13:40:47.474+0000] {local_task_job_runner.py:222} INFO - ::endgroup::
