[2024-04-27T15:41:38.535+0000] {taskinstance.py:1979} INFO - Dependencies all met for dep_context=non-requeueable deps ti=<TaskInstance: process_sales.extract_data_from_api scheduled__2022-08-09T01:00:00+00:00 [queued]>
[2024-04-27T15:41:38.545+0000] {taskinstance.py:1979} INFO - Dependencies all met for dep_context=requeueable deps ti=<TaskInstance: process_sales.extract_data_from_api scheduled__2022-08-09T01:00:00+00:00 [queued]>
[2024-04-27T15:41:38.545+0000] {taskinstance.py:2193} INFO - Starting attempt 4 of 5
[2024-04-27T15:41:38.566+0000] {taskinstance.py:2217} INFO - Executing <Task(PythonOperator): extract_data_from_api> on 2022-08-09 01:00:00+00:00
[2024-04-27T15:41:38.570+0000] {standard_task_runner.py:60} INFO - Started process 2306 to run task
[2024-04-27T15:41:38.572+0000] {standard_task_runner.py:87} INFO - Running: ['***', 'tasks', 'run', 'process_sales', 'extract_data_from_api', 'scheduled__2022-08-09T01:00:00+00:00', '--job-id', '36', '--raw', '--subdir', 'DAGS_FOLDER/process_sales.py', '--cfg-path', '/tmp/tmpaez_ipxb']
[2024-04-27T15:41:38.573+0000] {standard_task_runner.py:88} INFO - Job 36: Subtask extract_data_from_api
[2024-04-27T15:41:38.589+0000] {logging_mixin.py:188} WARNING - /home/***/.local/lib/python3.8/site-packages/***/settings.py:194 DeprecationWarning: The sql_alchemy_conn option in [core] has been moved to the sql_alchemy_conn option in [database] - the old setting has been used, but please update your config.
[2024-04-27T15:41:38.623+0000] {task_command.py:423} INFO - Running <TaskInstance: process_sales.extract_data_from_api scheduled__2022-08-09T01:00:00+00:00 [running]> on host 717551291b8f
[2024-04-27T15:41:38.707+0000] {taskinstance.py:2513} INFO - Exporting env vars: AIRFLOW_CTX_DAG_EMAIL='admin@admin.com' AIRFLOW_CTX_DAG_OWNER='***' AIRFLOW_CTX_DAG_ID='process_sales' AIRFLOW_CTX_TASK_ID='extract_data_from_api' AIRFLOW_CTX_EXECUTION_DATE='2022-08-09T01:00:00+00:00' AIRFLOW_CTX_TRY_NUMBER='4' AIRFLOW_CTX_DAG_RUN_ID='scheduled__2022-08-09T01:00:00+00:00'
[2024-04-27T15:41:38.708+0000] {logging_mixin.py:188} INFO - Starting job1:
[2024-04-27T15:41:38.713+0000] {taskinstance.py:2731} ERROR - Task failed with exception
Traceback (most recent call last):
  File "/home/airflow/.local/lib/python3.8/site-packages/urllib3/connection.py", line 174, in _new_conn
    conn = connection.create_connection(
  File "/home/airflow/.local/lib/python3.8/site-packages/urllib3/util/connection.py", line 95, in create_connection
    raise err
  File "/home/airflow/.local/lib/python3.8/site-packages/urllib3/util/connection.py", line 85, in create_connection
    sock.connect(sa)
ConnectionRefusedError: [Errno 111] Connection refused

During handling of the above exception, another exception occurred:

Traceback (most recent call last):
  File "/home/airflow/.local/lib/python3.8/site-packages/urllib3/connectionpool.py", line 715, in urlopen
    httplib_response = self._make_request(
  File "/home/airflow/.local/lib/python3.8/site-packages/urllib3/connectionpool.py", line 416, in _make_request
    conn.request(method, url, **httplib_request_kw)
  File "/home/airflow/.local/lib/python3.8/site-packages/urllib3/connection.py", line 244, in request
    super(HTTPConnection, self).request(method, url, body=body, headers=headers)
  File "/usr/local/lib/python3.8/http/client.py", line 1256, in request
    self._send_request(method, url, body, headers, encode_chunked)
  File "/usr/local/lib/python3.8/http/client.py", line 1302, in _send_request
    self.endheaders(body, encode_chunked=encode_chunked)
  File "/usr/local/lib/python3.8/http/client.py", line 1251, in endheaders
    self._send_output(message_body, encode_chunked=encode_chunked)
  File "/usr/local/lib/python3.8/http/client.py", line 1011, in _send_output
    self.send(msg)
  File "/usr/local/lib/python3.8/http/client.py", line 951, in send
    self.connect()
  File "/home/airflow/.local/lib/python3.8/site-packages/urllib3/connection.py", line 205, in connect
    conn = self._new_conn()
  File "/home/airflow/.local/lib/python3.8/site-packages/urllib3/connection.py", line 186, in _new_conn
    raise NewConnectionError(
urllib3.exceptions.NewConnectionError: <urllib3.connection.HTTPConnection object at 0x7fab7bbb3970>: Failed to establish a new connection: [Errno 111] Connection refused

During handling of the above exception, another exception occurred:

Traceback (most recent call last):
  File "/home/airflow/.local/lib/python3.8/site-packages/requests/adapters.py", line 486, in send
    resp = conn.urlopen(
  File "/home/airflow/.local/lib/python3.8/site-packages/urllib3/connectionpool.py", line 799, in urlopen
    retries = retries.increment(
  File "/home/airflow/.local/lib/python3.8/site-packages/urllib3/util/retry.py", line 592, in increment
    raise MaxRetryError(_pool, url, error or ResponseError(cause))
urllib3.exceptions.MaxRetryError: HTTPConnectionPool(host='localhost', port=8081): Max retries exceeded with url: / (Caused by NewConnectionError('<urllib3.connection.HTTPConnection object at 0x7fab7bbb3970>: Failed to establish a new connection: [Errno 111] Connection refused'))

During handling of the above exception, another exception occurred:

Traceback (most recent call last):
  File "/home/airflow/.local/lib/python3.8/site-packages/airflow/models/taskinstance.py", line 444, in _execute_task
    result = _execute_callable(context=context, **execute_callable_kwargs)
  File "/home/airflow/.local/lib/python3.8/site-packages/airflow/models/taskinstance.py", line 414, in _execute_callable
    return execute_callable(context=context, **execute_callable_kwargs)
  File "/home/airflow/.local/lib/python3.8/site-packages/airflow/operators/python.py", line 200, in execute
    return_value = self.execute_callable()
  File "/home/airflow/.local/lib/python3.8/site-packages/airflow/operators/python.py", line 217, in execute_callable
    return self.python_callable(*self.op_args, **self.op_kwargs)
  File "/opt/airflow/dags/process_sales.py", line 28, in run_job1
    resp = requests.post(
  File "/home/airflow/.local/lib/python3.8/site-packages/requests/api.py", line 115, in post
    return request("post", url, data=data, json=json, **kwargs)
  File "/home/airflow/.local/lib/python3.8/site-packages/requests/api.py", line 59, in request
    return session.request(method=method, url=url, **kwargs)
  File "/home/airflow/.local/lib/python3.8/site-packages/requests/sessions.py", line 589, in request
    resp = self.send(prep, **send_kwargs)
  File "/home/airflow/.local/lib/python3.8/site-packages/requests/sessions.py", line 703, in send
    r = adapter.send(request, **kwargs)
  File "/home/airflow/.local/lib/python3.8/site-packages/requests/adapters.py", line 519, in send
    raise ConnectionError(e, request=request)
requests.exceptions.ConnectionError: HTTPConnectionPool(host='localhost', port=8081): Max retries exceeded with url: / (Caused by NewConnectionError('<urllib3.connection.HTTPConnection object at 0x7fab7bbb3970>: Failed to establish a new connection: [Errno 111] Connection refused'))
[2024-04-27T15:41:38.729+0000] {taskinstance.py:1149} INFO - Marking task as UP_FOR_RETRY. dag_id=process_sales, task_id=extract_data_from_api, execution_date=20220809T010000, start_date=20240427T154138, end_date=20240427T154138
[2024-04-27T15:41:38.750+0000] {standard_task_runner.py:107} ERROR - Failed to execute job 36 for task extract_data_from_api (HTTPConnectionPool(host='localhost', port=8081): Max retries exceeded with url: / (Caused by NewConnectionError('<urllib3.connection.HTTPConnection object at 0x7fab7bbb3970>: Failed to establish a new connection: [Errno 111] Connection refused')); 2306)
[2024-04-27T15:41:38.785+0000] {local_task_job_runner.py:234} INFO - Task exited with return code 1
[2024-04-27T15:41:38.814+0000] {taskinstance.py:3312} INFO - 0 downstream tasks scheduled from follow-on schedule check
[2024-05-01T18:19:03.304+0000] {taskinstance.py:1979} INFO - Dependencies all met for dep_context=non-requeueable deps ti=<TaskInstance: process_sales.extract_data_from_api scheduled__2022-08-09T01:00:00+00:00 [queued]>
[2024-05-01T18:19:03.317+0000] {taskinstance.py:1979} INFO - Dependencies all met for dep_context=requeueable deps ti=<TaskInstance: process_sales.extract_data_from_api scheduled__2022-08-09T01:00:00+00:00 [queued]>
[2024-05-01T18:19:03.317+0000] {taskinstance.py:2193} INFO - Starting attempt 4 of 5
[2024-05-01T18:19:03.338+0000] {taskinstance.py:2217} INFO - Executing <Task(PythonOperator): extract_data_from_api> on 2022-08-09 01:00:00+00:00
[2024-05-01T18:19:03.343+0000] {standard_task_runner.py:60} INFO - Started process 965 to run task
[2024-05-01T18:19:03.346+0000] {standard_task_runner.py:87} INFO - Running: ['***', 'tasks', 'run', 'process_sales', 'extract_data_from_api', 'scheduled__2022-08-09T01:00:00+00:00', '--job-id', '81', '--raw', '--subdir', 'DAGS_FOLDER/process_sales.py', '--cfg-path', '/tmp/tmpsa7a7b6g']
[2024-05-01T18:19:03.348+0000] {standard_task_runner.py:88} INFO - Job 81: Subtask extract_data_from_api
[2024-05-01T18:19:03.367+0000] {logging_mixin.py:188} WARNING - /home/***/.local/lib/python3.8/site-packages/***/settings.py:194 DeprecationWarning: The sql_alchemy_conn option in [core] has been moved to the sql_alchemy_conn option in [database] - the old setting has been used, but please update your config.
[2024-05-01T18:19:03.411+0000] {task_command.py:423} INFO - Running <TaskInstance: process_sales.extract_data_from_api scheduled__2022-08-09T01:00:00+00:00 [running]> on host 717551291b8f
[2024-05-01T18:19:03.506+0000] {taskinstance.py:2513} INFO - Exporting env vars: AIRFLOW_CTX_DAG_EMAIL='admin@admin.com' AIRFLOW_CTX_DAG_OWNER='***' AIRFLOW_CTX_DAG_ID='process_sales' AIRFLOW_CTX_TASK_ID='extract_data_from_api' AIRFLOW_CTX_EXECUTION_DATE='2022-08-09T01:00:00+00:00' AIRFLOW_CTX_TRY_NUMBER='4' AIRFLOW_CTX_DAG_RUN_ID='scheduled__2022-08-09T01:00:00+00:00'
[2024-05-01T18:19:03.507+0000] {logging_mixin.py:188} INFO - Starting job1:
[2024-05-01T18:19:03.511+0000] {taskinstance.py:2731} ERROR - Task failed with exception
Traceback (most recent call last):
  File "/home/airflow/.local/lib/python3.8/site-packages/urllib3/connection.py", line 174, in _new_conn
    conn = connection.create_connection(
  File "/home/airflow/.local/lib/python3.8/site-packages/urllib3/util/connection.py", line 95, in create_connection
    raise err
  File "/home/airflow/.local/lib/python3.8/site-packages/urllib3/util/connection.py", line 85, in create_connection
    sock.connect(sa)
ConnectionRefusedError: [Errno 111] Connection refused

During handling of the above exception, another exception occurred:

Traceback (most recent call last):
  File "/home/airflow/.local/lib/python3.8/site-packages/urllib3/connectionpool.py", line 715, in urlopen
    httplib_response = self._make_request(
  File "/home/airflow/.local/lib/python3.8/site-packages/urllib3/connectionpool.py", line 416, in _make_request
    conn.request(method, url, **httplib_request_kw)
  File "/home/airflow/.local/lib/python3.8/site-packages/urllib3/connection.py", line 244, in request
    super(HTTPConnection, self).request(method, url, body=body, headers=headers)
  File "/usr/local/lib/python3.8/http/client.py", line 1256, in request
    self._send_request(method, url, body, headers, encode_chunked)
  File "/usr/local/lib/python3.8/http/client.py", line 1302, in _send_request
    self.endheaders(body, encode_chunked=encode_chunked)
  File "/usr/local/lib/python3.8/http/client.py", line 1251, in endheaders
    self._send_output(message_body, encode_chunked=encode_chunked)
  File "/usr/local/lib/python3.8/http/client.py", line 1011, in _send_output
    self.send(msg)
  File "/usr/local/lib/python3.8/http/client.py", line 951, in send
    self.connect()
  File "/home/airflow/.local/lib/python3.8/site-packages/urllib3/connection.py", line 205, in connect
    conn = self._new_conn()
  File "/home/airflow/.local/lib/python3.8/site-packages/urllib3/connection.py", line 186, in _new_conn
    raise NewConnectionError(
urllib3.exceptions.NewConnectionError: <urllib3.connection.HTTPConnection object at 0x7fbb5dbb0a30>: Failed to establish a new connection: [Errno 111] Connection refused

During handling of the above exception, another exception occurred:

Traceback (most recent call last):
  File "/home/airflow/.local/lib/python3.8/site-packages/requests/adapters.py", line 486, in send
    resp = conn.urlopen(
  File "/home/airflow/.local/lib/python3.8/site-packages/urllib3/connectionpool.py", line 799, in urlopen
    retries = retries.increment(
  File "/home/airflow/.local/lib/python3.8/site-packages/urllib3/util/retry.py", line 592, in increment
    raise MaxRetryError(_pool, url, error or ResponseError(cause))
urllib3.exceptions.MaxRetryError: HTTPConnectionPool(host='localhost', port=8081): Max retries exceeded with url: / (Caused by NewConnectionError('<urllib3.connection.HTTPConnection object at 0x7fbb5dbb0a30>: Failed to establish a new connection: [Errno 111] Connection refused'))

During handling of the above exception, another exception occurred:

Traceback (most recent call last):
  File "/home/airflow/.local/lib/python3.8/site-packages/airflow/models/taskinstance.py", line 444, in _execute_task
    result = _execute_callable(context=context, **execute_callable_kwargs)
  File "/home/airflow/.local/lib/python3.8/site-packages/airflow/models/taskinstance.py", line 414, in _execute_callable
    return execute_callable(context=context, **execute_callable_kwargs)
  File "/home/airflow/.local/lib/python3.8/site-packages/airflow/operators/python.py", line 200, in execute
    return_value = self.execute_callable()
  File "/home/airflow/.local/lib/python3.8/site-packages/airflow/operators/python.py", line 217, in execute_callable
    return self.python_callable(*self.op_args, **self.op_kwargs)
  File "/opt/airflow/dags/process_sales.py", line 29, in run_job1
    resp = requests.post(
  File "/home/airflow/.local/lib/python3.8/site-packages/requests/api.py", line 115, in post
    return request("post", url, data=data, json=json, **kwargs)
  File "/home/airflow/.local/lib/python3.8/site-packages/requests/api.py", line 59, in request
    return session.request(method=method, url=url, **kwargs)
  File "/home/airflow/.local/lib/python3.8/site-packages/requests/sessions.py", line 589, in request
    resp = self.send(prep, **send_kwargs)
  File "/home/airflow/.local/lib/python3.8/site-packages/requests/sessions.py", line 703, in send
    r = adapter.send(request, **kwargs)
  File "/home/airflow/.local/lib/python3.8/site-packages/requests/adapters.py", line 519, in send
    raise ConnectionError(e, request=request)
requests.exceptions.ConnectionError: HTTPConnectionPool(host='localhost', port=8081): Max retries exceeded with url: / (Caused by NewConnectionError('<urllib3.connection.HTTPConnection object at 0x7fbb5dbb0a30>: Failed to establish a new connection: [Errno 111] Connection refused'))
[2024-05-01T18:19:03.526+0000] {taskinstance.py:1149} INFO - Marking task as UP_FOR_RETRY. dag_id=process_sales, task_id=extract_data_from_api, execution_date=20220809T010000, start_date=20240501T181903, end_date=20240501T181903
[2024-05-01T18:19:03.540+0000] {standard_task_runner.py:107} ERROR - Failed to execute job 81 for task extract_data_from_api (HTTPConnectionPool(host='localhost', port=8081): Max retries exceeded with url: / (Caused by NewConnectionError('<urllib3.connection.HTTPConnection object at 0x7fbb5dbb0a30>: Failed to establish a new connection: [Errno 111] Connection refused')); 965)
[2024-05-01T18:19:03.559+0000] {local_task_job_runner.py:234} INFO - Task exited with return code 1
[2024-05-01T18:19:03.583+0000] {taskinstance.py:3312} INFO - 0 downstream tasks scheduled from follow-on schedule check
