[2024-05-15T20:54:47.164+0000] {local_task_job_runner.py:120} INFO - ::group::Pre task execution logs
[2024-05-15T20:54:47.199+0000] {taskinstance.py:2073} INFO - Dependencies all met for dep_context=non-requeueable deps ti=<TaskInstance: upload_csv_to_gcs_bucket.upload_task_1 scheduled__2022-08-15T00:00:00+00:00 [queued]>
[2024-05-15T20:54:47.219+0000] {taskinstance.py:2073} INFO - Dependencies all met for dep_context=requeueable deps ti=<TaskInstance: upload_csv_to_gcs_bucket.upload_task_1 scheduled__2022-08-15T00:00:00+00:00 [queued]>
[2024-05-15T20:54:47.221+0000] {taskinstance.py:2303} INFO - Starting attempt 15 of 15
[2024-05-15T20:54:47.255+0000] {taskinstance.py:2327} INFO - Executing <Task(LocalFilesystemToGCSOperator): upload_task_1> on 2022-08-15 00:00:00+00:00
[2024-05-15T20:54:47.267+0000] {warnings.py:110} WARNING - /home/***/.local/lib/python3.12/site-packages/***/task/task_runner/standard_task_runner.py:61: DeprecationWarning: This process (pid=271) is multi-threaded, use of fork() may lead to deadlocks in the child.
  pid = os.fork()

[2024-05-15T20:54:47.274+0000] {standard_task_runner.py:63} INFO - Started process 284 to run task
[2024-05-15T20:54:47.274+0000] {standard_task_runner.py:90} INFO - Running: ['***', 'tasks', 'run', 'upload_csv_to_gcs_bucket', 'upload_task_1', 'scheduled__2022-08-15T00:00:00+00:00', '--job-id', '932', '--raw', '--subdir', 'DAGS_FOLDER/gcp_csv_upload.py', '--cfg-path', '/tmp/tmpiz6htd_v']
[2024-05-15T20:54:47.281+0000] {standard_task_runner.py:91} INFO - Job 932: Subtask upload_task_1
[2024-05-15T20:54:47.308+0000] {warnings.py:110} WARNING - /home/***/.local/lib/python3.12/site-packages/***/settings.py:195: DeprecationWarning: The sql_alchemy_conn option in [core] has been moved to the sql_alchemy_conn option in [database] - the old setting has been used, but please update your config.
  SQL_ALCHEMY_CONN = conf.get("database", "SQL_ALCHEMY_CONN")

[2024-05-15T20:54:47.399+0000] {task_command.py:426} INFO - Running <TaskInstance: upload_csv_to_gcs_bucket.upload_task_1 scheduled__2022-08-15T00:00:00+00:00 [running]> on host e9b4a57d7285
[2024-05-15T20:54:47.593+0000] {taskinstance.py:2644} INFO - Exporting env vars: AIRFLOW_CTX_DAG_OWNER='***' AIRFLOW_CTX_DAG_ID='upload_csv_to_gcs_bucket' AIRFLOW_CTX_TASK_ID='upload_task_1' AIRFLOW_CTX_EXECUTION_DATE='2022-08-15T00:00:00+00:00' AIRFLOW_CTX_TRY_NUMBER='15' AIRFLOW_CTX_DAG_RUN_ID='scheduled__2022-08-15T00:00:00+00:00'
[2024-05-15T20:54:47.598+0000] {taskinstance.py:430} INFO - ::endgroup::
[2024-05-15T20:54:47.645+0000] {connection.py:274} WARNING - Connection schemes (type: google_cloud_platform) shall not contain '_' according to RFC3986.
[2024-05-15T20:54:47.657+0000] {base.py:84} INFO - Using connection ID 'google_cloud_default' for task execution.
[2024-05-15T20:54:47.659+0000] {taskinstance.py:441} INFO - ::group::Post task execution logs
[2024-05-15T20:54:47.661+0000] {taskinstance.py:2890} ERROR - Task failed with exception
Traceback (most recent call last):
  File "/home/airflow/.local/lib/python3.12/site-packages/airflow/models/taskinstance.py", line 465, in _execute_task
    result = _execute_callable(context=context, **execute_callable_kwargs)
             ^^^^^^^^^^^^^^^^^^^^^^^^^^^^^^^^^^^^^^^^^^^^^^^^^^^^^^^^^^^^^
  File "/home/airflow/.local/lib/python3.12/site-packages/airflow/models/taskinstance.py", line 432, in _execute_callable
    return execute_callable(context=context, **execute_callable_kwargs)
           ^^^^^^^^^^^^^^^^^^^^^^^^^^^^^^^^^^^^^^^^^^^^^^^^^^^^^^^^^^^^
  File "/home/airflow/.local/lib/python3.12/site-packages/airflow/models/baseoperator.py", line 400, in wrapper
    return func(self, *args, **kwargs)
           ^^^^^^^^^^^^^^^^^^^^^^^^^^^
  File "/home/airflow/.local/lib/python3.12/site-packages/airflow/providers/google/cloud/transfers/local_to_gcs.py", line 97, in execute
    raise FileNotFoundError(self.src)
FileNotFoundError: /data/sales_2022-08-15.csv
[2024-05-15T20:54:47.679+0000] {taskinstance.py:1205} INFO - Marking task as FAILED. dag_id=upload_csv_to_gcs_bucket, task_id=upload_task_1, execution_date=20220815T000000, start_date=20240515T205447, end_date=20240515T205447
[2024-05-15T20:54:47.707+0000] {standard_task_runner.py:110} ERROR - Failed to execute job 932 for task upload_task_1 (/data/sales_2022-08-15.csv; 284)
[2024-05-15T20:54:47.746+0000] {local_task_job_runner.py:240} INFO - Task exited with return code 1
[2024-05-15T20:54:47.775+0000] {taskinstance.py:3482} INFO - 0 downstream tasks scheduled from follow-on schedule check
[2024-05-15T20:54:47.779+0000] {local_task_job_runner.py:222} INFO - ::endgroup::
