[2024-05-15T20:20:43.245+0000] {local_task_job_runner.py:120} INFO - ::group::Pre task execution logs
[2024-05-15T20:20:43.276+0000] {taskinstance.py:2063} INFO - Dependencies not met for <TaskInstance: upload_csv_to_gcs_bucket.upload_task_0 scheduled__2022-08-11T00:00:00+00:00 [queued]>, dependency 'Execution Date' FAILED: The execution date is 2022-08-11T00:00:00+00:00 but this is after the task's end date 2022-08-10T00:00:00+00:00.
[2024-05-15T20:20:43.287+0000] {local_task_job_runner.py:163} INFO - Task is not able to be run
[2024-05-15T20:54:52.027+0000] {local_task_job_runner.py:120} INFO - ::group::Pre task execution logs
[2024-05-15T20:54:52.047+0000] {taskinstance.py:2073} INFO - Dependencies all met for dep_context=non-requeueable deps ti=<TaskInstance: upload_csv_to_gcs_bucket.upload_task_0 scheduled__2022-08-11T00:00:00+00:00 [queued]>
[2024-05-15T20:54:52.058+0000] {taskinstance.py:2073} INFO - Dependencies all met for dep_context=requeueable deps ti=<TaskInstance: upload_csv_to_gcs_bucket.upload_task_0 scheduled__2022-08-11T00:00:00+00:00 [queued]>
[2024-05-15T20:54:52.058+0000] {taskinstance.py:2303} INFO - Starting attempt 12 of 13
[2024-05-15T20:54:52.074+0000] {taskinstance.py:2327} INFO - Executing <Task(LocalFilesystemToGCSOperator): upload_task_0> on 2022-08-11 00:00:00+00:00
[2024-05-15T20:54:52.081+0000] {warnings.py:110} WARNING - /home/***/.local/lib/python3.12/site-packages/***/task/task_runner/standard_task_runner.py:61: DeprecationWarning: This process (pid=324) is multi-threaded, use of fork() may lead to deadlocks in the child.
  pid = os.fork()

[2024-05-15T20:54:52.083+0000] {standard_task_runner.py:63} INFO - Started process 330 to run task
[2024-05-15T20:54:52.083+0000] {standard_task_runner.py:90} INFO - Running: ['***', 'tasks', 'run', 'upload_csv_to_gcs_bucket', 'upload_task_0', 'scheduled__2022-08-11T00:00:00+00:00', '--job-id', '956', '--raw', '--subdir', 'DAGS_FOLDER/gcp_csv_upload.py', '--cfg-path', '/tmp/tmp32e4rhn4']
[2024-05-15T20:54:52.085+0000] {standard_task_runner.py:91} INFO - Job 956: Subtask upload_task_0
[2024-05-15T20:54:52.100+0000] {warnings.py:110} WARNING - /home/***/.local/lib/python3.12/site-packages/***/settings.py:195: DeprecationWarning: The sql_alchemy_conn option in [core] has been moved to the sql_alchemy_conn option in [database] - the old setting has been used, but please update your config.
  SQL_ALCHEMY_CONN = conf.get("database", "SQL_ALCHEMY_CONN")

[2024-05-15T20:54:52.135+0000] {task_command.py:426} INFO - Running <TaskInstance: upload_csv_to_gcs_bucket.upload_task_0 scheduled__2022-08-11T00:00:00+00:00 [running]> on host e9b4a57d7285
[2024-05-15T20:54:52.228+0000] {taskinstance.py:2644} INFO - Exporting env vars: AIRFLOW_CTX_DAG_OWNER='***' AIRFLOW_CTX_DAG_ID='upload_csv_to_gcs_bucket' AIRFLOW_CTX_TASK_ID='upload_task_0' AIRFLOW_CTX_EXECUTION_DATE='2022-08-11T00:00:00+00:00' AIRFLOW_CTX_TRY_NUMBER='12' AIRFLOW_CTX_DAG_RUN_ID='scheduled__2022-08-11T00:00:00+00:00'
[2024-05-15T20:54:52.229+0000] {taskinstance.py:430} INFO - ::endgroup::
[2024-05-15T20:54:52.255+0000] {connection.py:274} WARNING - Connection schemes (type: google_cloud_platform) shall not contain '_' according to RFC3986.
[2024-05-15T20:54:52.261+0000] {base.py:84} INFO - Using connection ID 'google_cloud_default' for task execution.
[2024-05-15T20:54:52.262+0000] {taskinstance.py:441} INFO - ::group::Post task execution logs
[2024-05-15T20:54:52.263+0000] {taskinstance.py:2890} ERROR - Task failed with exception
Traceback (most recent call last):
  File "/home/airflow/.local/lib/python3.12/site-packages/airflow/models/taskinstance.py", line 465, in _execute_task
    result = _execute_callable(context=context, **execute_callable_kwargs)
             ^^^^^^^^^^^^^^^^^^^^^^^^^^^^^^^^^^^^^^^^^^^^^^^^^^^^^^^^^^^^^
  File "/home/airflow/.local/lib/python3.12/site-packages/airflow/models/taskinstance.py", line 432, in _execute_callable
    return execute_callable(context=context, **execute_callable_kwargs)
           ^^^^^^^^^^^^^^^^^^^^^^^^^^^^^^^^^^^^^^^^^^^^^^^^^^^^^^^^^^^^
  File "/home/airflow/.local/lib/python3.12/site-packages/airflow/models/baseoperator.py", line 400, in wrapper
    return func(self, *args, **kwargs)
           ^^^^^^^^^^^^^^^^^^^^^^^^^^^
  File "/home/airflow/.local/lib/python3.12/site-packages/airflow/providers/google/cloud/transfers/local_to_gcs.py", line 97, in execute
    raise FileNotFoundError(self.src)
FileNotFoundError: /data/sales_2022-08-11.csv
[2024-05-15T20:54:52.272+0000] {taskinstance.py:1205} INFO - Marking task as UP_FOR_RETRY. dag_id=upload_csv_to_gcs_bucket, task_id=upload_task_0, execution_date=20220811T000000, start_date=20240515T205452, end_date=20240515T205452
[2024-05-15T20:54:52.288+0000] {standard_task_runner.py:110} ERROR - Failed to execute job 956 for task upload_task_0 (/data/sales_2022-08-11.csv; 330)
[2024-05-15T20:54:52.296+0000] {local_task_job_runner.py:240} INFO - Task exited with return code 1
[2024-05-15T20:54:52.314+0000] {taskinstance.py:3482} INFO - 0 downstream tasks scheduled from follow-on schedule check
[2024-05-15T20:54:52.317+0000] {local_task_job_runner.py:222} INFO - ::endgroup::
